# 错误厝里

    捕获错误  try....catch
        try{
            这里会捕获到异常
        }catch(error) {
            这里的处理异常
            触发条件：try里面的代码块有如果有错误或者抛出异常，catch就会执行 ，
        }
    抛出异常    throw 
    两个的不同：  使用try  catch 是用来捕获错误，他后面的代码依然可以执行，
                使用throw 系统就会报错，后面的代码不会执行 
    Error 错误对象，有一个参数，错误信息


    "proxy" :{
    "/api": {
      "target": "http://47.93.114.103:6688/manage", 
      "changeOrigin": true,
      "pathRewrite": { "^/api": "/" }
    }
  }